Workbook

Sheet Policías
A1: PLANTILLA POLICIA LOCAL
A2: Base de datos central de policías
A4: ID Empleado | B4: Nombre y Apellidos | C4: Categoría | D4: DIP | E4: Grupo
A5: 101 | B5: Francisca | C5: Inspectora | D5: 1 | E5: Jefatura
A6: 102 | B6: Manuel | C6: Subinspector | D6: 2 | E6: Jefatura
A7: 103 | B7: Juan | C7: Oficial Policía | D7: 3 | E7: Prommesas
A8: 104 | B8: Diego | C8: Oficial Policía | D8: 4
A9: 105 | B9: Adrián | C9: Oficial Policía | D9: 5 | E9: Grupo 3
A10: 106 | B10: Juan Rafael | C10: Oficial Policía | D10: 6 | E10: Grupo 2
A11: 107 | B11: Matías | C11: Oficial Policía | D11: 7 | E11: Grupo 1
A12: 108 | B12: Manuel 2 | C12: Oficial Policía | D12: 8 | E12: Grupo 5
A13: 109 | B13: Manuel 3 | C13: Oficial Policía Organizativo | D13: 9 | E13: Jefatura
A14: 110 | B14: Julián | C14: Policía | D14: 10 | E14: Jefatura
A15: 111 | B15: Rocío | C15: Policía | D15: 11 | E15: Prommesas
A16: 112 | B16: Juan Jesús | C16: Policía | D16: 12 | E16: Grupo 5
A17: 113 | B17: Jorge | C17: Policía | D17: 13 | E17: Grupo 3
A18: 114 | B18: Maria José | C18: Policía | D18: 14 | E18: Jefatura
A19: 115 | B19: Martín Francisco | C19: Policía | D19: 15 | E19: Grupo 6
A20: 116 | B20: Bartolomé | C20: Policía | D20: 16 | E20: Grupo 4
... A36: 132 | B36: Juan Antonio | C36: Policía | D36: 32 | E36: Grupo 1
A37: 133 | B37: Jose Manuel | C37: Policía | D37: 33
A38: 134 | B38: José Antonio | C38: Policía | D38: 34 | E38: Grupo 1
A39: 135 | B39: Yolanda | C39: Policía | D39: 35 | E39: Grupo 4
A40: 136 | B40: Narciso | C40: Policía | D40: 36 | E40: Grupo 1
A41: 137 | B41: José Díaz | C41: Policía | D41: 37 | E41: Grupo 6
A42: 138 | B42: Fernando | C42: Policía | D42: 38 | E42: Grupo 4
A43: 139 | B43: Juan | C43: Policía | D43: 39 | E43: Grupo 5
A44: 140 | B44: Gonzalez | C44: Policía | D44: 40 | E44: Grupo 3
A45: 141 | B45: Diego José | C45: Policía | D45: 41 | E45: Grupo 3
A46: 142 | B46: Morales | C46: Policía | D46: 42 | E46: Grupo 6
A47: 143 | B47: Rafael | C47: Policía | D47: 43 | E47: Grupo 3
A48: 144 | B48: Moisés | C48: Policía | D48: 44 | E48: Grupo 3
A49: 145 | B49: Delgado | C49: Policía | D49: 45 | E49: Grupo 1
... A63: 159 | B63: Muriel | C63: Policía | D63: 59 | E63: Grupo 2

Sheet Cuadrante
A1: CUADRANTE ANUAL DE TURNOS
A2: M: Mañana | T: Tarde | N: Noche | D: Descanso / Libre | VAC: Vacaciones | BAJA: Baja | AP: Asuntos Propios | HS: Horas Sindicales
A4: ID | B4: Empleado | C4: Categoría | D4: Grupo | E4: 01/08/2026 | F4: 02/08/2026 | G4: 03/08/2026 | H4: 04/08/2026 | I4: 05/08/2026 | J4: 06/08/2026 | K4: 07/08/2026 | L4: 08/08/2026 | M4: 09/08/2026 | N4: 10/08/2026 | O4: 11/08/2026 | P4: 12/08/2026 | Q4: 13/08/2026 | R4: 14/08/2026 | S4: 15/08/2026 | T4: 16/08/2026 | U4: 17/08/2026 | V4: 18/08/2026 | W4: 19/08/2026 | X4: 20/08/2026 | Y4: 21/08/2026 | Z4: 22/08/2026 | AA4: 23/08/2026 | AB4: 24/08/2026 | AC4: 25/08/2026 | AD4: 26/08/2026 | AE4: 27/08/2026 | AF4: 28/08/2026 | AG4: 29/08/2026 | AH4: 30/08/2026 | AI4: 31/08/2026 | AJ4: 01/09/2026 | AK4: 02/09/2026 | AL4: 03/09/2026 | AM4: 04/09/2026 | AN4: 05/09/2026 | AO4: 06/09/2026 | AP4: 07/09/2026 | AQ4: 08/09/2026 | AR4: 09/09/2026 | AS4: 10/09/2026 | AT4: 11/09/2026 | AU4: 12/09/2026 | AV4: 13/09/2026 | AW4: 14/09/2026 | AX4: 15/09/2026 | AY4: 16/09/2026 | AZ4: 17/09/2026 | BA4: 18/09/2026 | BB4: 19/09/2026 | BC4: 20/09/2026 | BD4: 21/09/2026 | BE4: 22/09/2026 | BF4: 23/09/2026 | BG4: 24/09/2026 | BH4: 25/09/2026 | BI4: 26/09/2026 | BJ4: 27/09/2026 | BK4: 28/09/2026 | BL4: 29/09/2026 | BM4: 30/09/2026
A5: =Policías!A5 -> 101 | B5: =Policías!B5 -> Francisca | C5: =Policías!C5 -> Inspectora | D5: Jefatura | E5: D | F5: D | G5: M | H5: M | I5: M | J5: M | K5: M | L5: D | M5: D | N5: M | O5: M | P5: M | Q5: M | R5: M | S5: D | T5: D | U5: M | V5: M | W5: M | X5: D | Y5: M | Z5: D | AA5: D | AB5: M | AC5: M | AD5: M | AE5: M | AF5: M | AG5: D | AH5: D | AI5: M | AJ5: M | AK5: M | AL5: M | AM5: M | AN5: D | AO5: D | AP5: M | AQ5: M | AR5: M | AS5: M | AT5: M | AU5: D | AV5: D | AW5: M | AX5: M | AY5: M | AZ5: M | BA5: M | BB5: D | BC5: D | BD5: M | BE5: M | BF5: M | BG5: M | BH5: M | BI5: D | BJ5: D | BK5: M | BL5: M | BM5: M
A6: =Policías!A6 -> 102 | B6: =Policías!B6 -> Manuel | C6: =Policías!C6 -> Subinspector | D6: Jefatura | E6: D | F6: D | G6: M | H6: M | I6: M | J6: M | K6: M | L6: D | M6: D | N6: M | O6: M | P6: M | Q6: M | R6: M | S6: D | T6: D | U6: M | V6: M | W6: M | X6: D | Y6: M | Z6: D | AA6: D | AB6: M | AC6: M | AD6: M | AE6: M | AF6: M | AG6: D | AH6: D | AI6: M | AJ6: M | AK6: M | AL6: M | AM6: M | AN6: D | AO6: D | AP6: M | AQ6: M | AR6: M | AS6: M | AT6: M | AU6: D | AV6: D | AW6: M | AX6: M | AY6: M | AZ6: M | BA6: M | BB6: D | BC6: D | BD6: M | BE6: M | BF6: M | BG6: M | BH6: M | BI6: D | BJ6: D | BK6: M | BL6: M | BM6: M
A7: =Policías!A7 -> 103 | B7: =Policías!B7 -> Juan | C7: =Policías!C7 -> Oficial Policía | D7: Prommesas | E7: D | F7: D | G7: M | H7: M | I7: M | J7: M | K7: M | L7: D | M7: D | N7: D | O7: D | P7: M | Q7: M | R7: M | S7: M | T7: M | U7: D | V7: D | W7: D | X7: D | Y7: M | Z7: M | AA7: M | AB7: M | AC7: M | AD7: D | AE7: D | AF7: D | AG7: D | AH7: M | AI7: M | AJ7: M | AK7: M | AL7: M | AM7: M | AN7: D | AO7: D | AP7: M | AQ7: M | AR7: M | AS7: M | AT7: M | AU7: D | AV7: D | AW7: M | AX7: M | AY7: M | AZ7: M | BA7: M | BB7: D | BC7: D | BD7: M | BE7: M | BF7: M | BG7: M | BH7: M | BI7: D | BJ7: D | BK7: M | BL7: M | BM7: M
A8: =Policías!A8 -> 104 | B8: =Policías!B8 -> Diego | C8: =Policías!C8 -> Oficial Policía | E8: BAJA | F8: BAJA | G8: BAJA | H8: BAJA | I8: BAJA | J8: BAJA | K8: BAJA | L8: BAJA | M8: BAJA | N8: BAJA | O8: BAJA | P8: BAJA | Q8: BAJA | R8: BAJA | S8: BAJA | T8: BAJA | U8: BAJA | V8: BAJA | W8: BAJA | X8: BAJA | Y8: BAJA | Z8: BAJA | AA8: BAJA | AB8: BAJA | AC8: BAJA | AD8: BAJA | AE8: BAJA | AF8: BAJA | AG8: BAJA | AH8: BAJA | AI8: BAJA
A9: =Policías!A9 -> 105 | B9: =Policías!B9 -> Adrián | C9: =Policías!C9 -> Oficial Policía | D9: Grupo 3 | E9: D | F9: D | G9: M | H9: M | I9: T | J9: T | K9: N | L9: N | M9: D | N9: D | O9: D | P9: D | Q9: D | R9: D | S9: D | T9: D | U9: M | V9: M | W9: T | X9: T | Y9: N | Z9: N | AA9: D | AB9: D | AC9: D | AD9: D | AE9: D | AF9: D | AG9: M | AH9: M | AI9: T
A10: =Policías!A10 -> 106 | B10: =Policías!B10 -> Juan Rafael | C10: =Policías!C10 -> Oficial Policía | D10: Grupo 2 | E10: M | F10: M | G10: T | H10: T | I10: N | J10: N | K10: D | L10: D | M10: D | N10: D | O10: D | P10: D | Q10: M | R10: M | S10: T | T10: T | U10: N | V10: N | W10: D | X10: D | Y10: D | Z10: D | AA10: D | AB10: D | AC10: M | AD10: M | AE10: T | AF10: T | AG10: N | AH10: N | AI10: D
A11: =Policías!A11 -> 107 | B11: =Policías!B11 -> Matías | C11: =Policías!C11 -> Oficial Policía | D11: Grupo 1 | E11: D | F11: D | G11: D | H11: D | I11: M | J11: M | K11: T | L11: T | M11: N | N11: N | O11: D | P11: D | Q11: D | R11: D | S11: D | T11: D | U11: M | V11: M | W11: T | X11: T | Y11: N | Z11: N | AA11: D | AB11: D | AC11: D | AD11: D | AE11: D | AF11: D | AG11: M | AH11: M | AI11: T | AJ11: T | AK11: N | AL11: N | AM11: D | AN11: D | AO11: D | AP11: D | AQ11: D | AR11: D | AS11: M | AT11: M | AU11: T | AV11: T | AW11: N | AX11: N | AY11: D | AZ11: D | BA11: D | BB11: D | BC11: D | BD11: D | BE11: M | BF11: M | BG11: T | BH11: T | BI11: N | BJ11: N | BK11: D | BL11: D | BM11: D
A12: =Policías!A12 -> 108 | B12: =Policías!B12 -> Manuel 2 | C12: =Policías!C12 -> Oficial Policía | D12: Grupo 5 | E12: D | F12: D | G12: D | H12: D | I12: D | J12: D | K12: M | L12: M | M12: T | N12: T | O12: N | P12: N | Q12: D | R12: D | S12: D | T12: D | U12: D | V12: D | W12: M | X12: M | Y12: T | Z12: T | AA12: N | AB12: N | AC12: D | AD12: D | AE12: D | AF12: D | AG12: D | AH12: D | AI12: M
A13: =Policías!A13 -> 109 | B13: =Policías!B13 -> Manuel 3 | C13: =Policías!C13 -> Oficial Policía Organizativo | D13: Jefatura | E13: D | F13: D | G13: M | H13: M | I13: M | J13: M | K13: M | L13: D | M13: D | N13: M | O13: M | P13: M | Q13: M | R13: M | S13: D | T13: D | U13: M | V13: M | W13: M | X13: D | Y13: M | Z13: D | AA13: D | AB13: M | AC13: M | AD13: M | AE13: M | AF13: M | AG13: D | AH13: D | AI13: M | AJ13: M | AK13: M | AL13: M | AM13: M | AN13: D | AO13: D | AP13: M | AQ13: M | AR13: M | AS13: M | AT13: M | AU13: D | AV13: D | AW13: M | AX13: M | AY13: M | AZ13: M | BA13: M | BB13: D | BC13: D | BD13: M | BE13: M | BF13: M | BG13: M | BH13: M | BI13: D | BJ13: D | BK13: M | BL13: M | BM13: M
A14: =Policías!A14 -> 110 | B14: =Policías!B14 -> Julián | C14: =Policías!C14 -> Policía | D14: Jefatura | E14: D | F14: D | G14: M | H14: M | I14: M | J14: M | K14: M | L14: D | M14: D | N14: M | O14: M | P14: M | Q14: M | R14: M | S14: D | T14: D | U14: M | V14: M | W14: M | X14: D | Y14: M | Z14: D | AA14: D | AB14: M | AC14: M | AD14: M | AE14: M | AF14: M | AG14: D | AH14: D | AI14: M | AJ14: M | AK14: M | AL14: M | AM14: M | AN14: D | AO14: D | AP14: M | AQ14: M | AR14: M | AS14: M | AT14: M | AU14: D | AV14: D | AW14: M | AX14: M | AY14: M | AZ14: M | BA14: M | BB14: D | BC14: D | BD14: M | BE14: M | BF14: M | BG14: M | BH14: M | BI14: D | BJ14: D | BK14: M | BL14: M | BM14: M
A15: =Policías!A15 -> 111 | B15: =Policías!B15 -> Rocío | C15: =Policías!C15 -> Policía | D15: Prommesas | E15: D | F15: D | G15: M | H15: M | I15: M | J15: M | K15: M | L15: D | M15: D | N15: D | O15: D | P15: M | Q15: M | R15: M | S15: M | T15: M | U15: D | V15: D | W15: D | X15: D | Y15: M | Z15: M | AA15: M | AB15: M | AC15: M | AD15: D | AE15: D | AF15: D | AG15: D | AH15: M | AI15: M | AJ15: M | AK15: M | AL15: M | AM15: M | AN15: D | AO15: D | AP15: M | AQ15: M | AR15: M | AS15: M | AT15: M | AU15: D | AV15: D | AW15: M | AX15: M | AY15: M | AZ15: M | BA15: M | BB15: D | BC15: D | BD15: M | BE15: M | BF15: M | BG15: M | BH15: M | BI15: D | BJ15: D | BK15: M | BL15: M | BM15: M
A16: =Policías!A16 -> 112 | B16: =Policías!B16 -> Juan Jesús | C16: =Policías!C16 -> Policía | D16: Grupo 5 | E16: D | F16: D | G16: D | H16: D | I16: D | J16: D | K16: M | L16: M | M16: T | N16: T | O16: N | P16: N | Q16: D | R16: D | S16: D | T16: D | U16: D | V16: D | W16: M | X16: M | Y16: T | Z16: T | AA16: N | AB16: N | AC16: D | AD16: D | AE16: D | AF16: D | AG16: D | AH16: D | AI16: M
A17: =Policías!A17 -> 113 | B17: =Policías!B17 -> Jorge | C17: =Policías!C17 -> Policía | D17: Grupo 3 | E17: D | F17: D | G17: M | H17: M | I17: T | J17: T | K17: N | L17: N | M17: D | N17: D | O17: D | P17: D | Q17: D | R17: D | S17: D | T17: D | U17: M | V17: M | W17: T | X17: T | Y17: N | Z17: N | AA17: D | AB17: D | AC17: D | AD17: D | AE17: D | AF17: D | AG17: M | AH17: M | AI17: T
A18: =Policías!A18 -> 114 | B18: =Policías!B18 -> Maria José | C18: =Policías!C18 -> Policía | D18: Jefatura | E18: D | F18: D | G18: M | H18: M | I18: M | J18: M | K18: M | L18: D | M18: D | N18: M | O18: M | P18: M | Q18: M | R18: M | S18: D | T18: D | U18: M | V18: M | W18: M | X18: D | Y18: M | Z18: D | AA18: D | AB18: M | AC18: M | AD18: M | AE18: M | AF18: M | AG18: D | AH18: D | AI18: M | AJ18: M | AK18: M | AL18: M | AM18: M | AN18: D | AO18: D | AP18: M | AQ18: M | AR18: M | AS18: M | AT18: M | AU18: D | AV18: D | AW18: M | AX18: M | AY18: M | AZ18: M | BA18: M | BB18: D | BC18: D | BD18: M | BE18: M | BF18: M | BG18: M | BH18: M | BI18: D | BJ18: D | BK18: M | BL18: M | BM18: M
A19: =Policías!A19 -> 115 | B19: =Policías!B19 -> Martín Francisco | C19: =Policías!C19 -> Policía | D19: Grupo 6 | E19: N | F19: N | G19: D | H19: D | I19: D | J19: D | K19: D | L19: D | M19: M | N19: M | O19: T | P19: T | Q19: N | R19: N | S19: D | T19: D | U19: D | V19: D | W19: D | X19: D | Y19: M | Z19: M | AA19: T | AB19: T | AC19: N | AD19: N | AE19: D | AF19: D | AG19: D | AH19: D | AI19: D
A20: =Policías!A20 -> 116 | B20: =Policías!B20 -> Bartolomé | C20: =Policías!C20 -> Policía | D20: Grupo 4 | E20: T | F20: T | G20: N | H20: N | I20: D | J20: D | K20: D | L20: D | M20: D | N20: D | O20: M | P20: M | Q20: T | R20: T | S20: N | T20: N | U20: D | V20: D | W20: D | X20: D | Y20: D | Z20: D | AA20: M | AB20: M | AC20: T | AD20: T | AE20: N | AF20: N | AG20: D | AH20: D | AI20: D
A21: =Policías!A21 -> 117 | B21: =Policías!B21 -> Miguel Ángel | C21: =Policías!C21 -> Policía | D21: Grupo 1 | E21: D | F21: D | G21: D | H21: D | I21: M | J21: M | K21: T | L21: T | M21: N | N21: N | O21: D | P21: D | Q21: D | R21: D | S21: D | T21: D | U21: M | V21: M | W21: T | X21: T | Y21: N | Z21: N | AA21: D | AB21: D | AC21: D | AD21: D | AE21: D | AF21: D | AG21: M | AH21: M | AI21: T | AJ21: T | AK21: N | AL21: N | AM21: D | AN21: D | AO21: D | AP21: D | AQ21: D | AR21: D | AS21: M | AT21: M | AU21: T | AV21: T | AW21: N | AX21: N | AY21: D | AZ21: D | BA21: D | BB21: D | BC21: D | BD21: D | BE21: M | BF21: M | BG21: T | BH21: T | BI21: N | BJ21: N | BK21: D | BL21: D | BM21: D
A22: =Policías!A22 -> 118 | B22: =Policías!B22 -> José | C22: =Policías!C22 -> Policía | D22: Grupo 2 | E22: M | F22: M | G22: T | H22: T | I22: N | J22: N | K22: D | L22: D | M22: D | N22: D | O22: D | P22: D | Q22: M | R22: M | S22: T | T22: T | U22: N | V22: N | W22: D | X22: D | Y22: D | Z22: D | AA22: D | AB22: D | AC22: M | AD22: M | AE22: T | AF22: T | AG22: N | AH22: N | AI22: D
A23: =Policías!A23 -> 119 | B23: =Policías!B23 -> Francisco José | C23: =Policías!C23 -> Policía | D23: Jefatura | E23: D | F23: D | G23: M | H23: M | I23: M | J23: M | K23: M | L23: D | M23: D | N23: M | O23: M | P23: M | Q23: M | R23: M | S23: D | T23: D | U23: M | V23: M | W23: M | X23: D | Y23: M | Z23: D | AA23: D | AB23: M | AC23: M | AD23: M | AE23: M | AF23: M | AG23: D | AH23: D | AI23: M | AJ23: M | AK23: M | AL23: M | AM23: M | AN23: D | AO23: D | AP23: M | AQ23: M | AR23: M | AS23: M | AT23: M | AU23: D | AV23: D | AW23: M | AX23: M | AY23: M | AZ23: M | BA23: M | BB23: D | BC23: D | BD23: M | BE23: M | BF23: M | BG23: M | BH23: M | BI23: D | BJ23: D | BK23: M | BL23: M | BM23: M
A24: =Policías!A24 -> 120 | B24: =Policías!B24 -> Jose Antonio | C24: =Policías!C24 -> Policía | D24: Grupo 5 | E24: D | F24: D | G24: D | H24: D | I24: D | J24: D | K24: M | L24: M | M24: T | N24: T | O24: N | P24: N | Q24: D | R24: D | S24: D | T24: D | U24: D | V24: D | W24: M | X24: M | Y24: T | Z24: T | AA24: N | AB24: N | AC24: D | AD24: D | AE24: D | AF24: D | AG24: D | AH24: D | AI24: M
A25: =Policías!A25 -> 121 | B25: =Policías!B25 -> De la Torre | C25: =Policías!C25 -> Policía | D25: Grupo 6 | E25: N | F25: N | G25: D | H25: D | I25: D | J25: D | K25: D | L25: D | M25: M | N25: M | O25: T | P25: T | Q25: N | R25: N | S25: D | T25: D | U25: D | V25: D | W25: D | X25: D | Y25: M | Z25: M | AA25: T | AB25: T | AC25: N | AD25: N | AE25: D | AF25: D | AG25: D | AH25: D | AI25: D
A26: =Policías!A26 -> 122 | B26: =Policías!B26 -> Bartolomé 2 | C26: =Policías!C26 -> Policía | D26: Grupo 4 | E26: T | F26: T | G26: N | H26: N | I26: D | J26: D | K26: D | L26: D | M26: D | N26: D | O26: M | P26: M | Q26: T | R26: T | S26: N | T26: N | U26: D | V26: D | W26: D | X26: D | Y26: D | Z26: D | AA26: M | AB26: M | AC26: T | AD26: T | AE26: N | AF26: N | AG26: D | AH26: D | AI26: D
A27: =Policías!A27 -> 123 | B27: =Policías!B27 -> Pedro | C27: =Policías!C27 -> Policía | D27: Grupo 4 | E27: T | F27: T | G27: N | H27: N | I27: D | J27: D | K27: D | L27: D | M27: D | N27: D | O27: M | P27: M | Q27: T | R27: T | S27: N | T27: N | U27: D | V27: D | W27: D | X27: D | Y27: D | Z27: D | AA27: M | AB27: M | AC27: T | AD27: T | AE27: N | AF27: N | AG27: D | AH27: D | AI27: D
A28: =Policías!A28 -> 124 | B28: =Policías!B28 -> José María | C28: =Policías!C28 -> Policía | D28: Jefatura | E28: D | F28: D | G28: M | H28: M | I28: M | J28: M | K28: M | L28: D | M28: D | N28: M | O28: M | P28: M | Q28: M | R28: M | S28: D | T28: D | U28: M | V28: M | W28: M | X28: D | Y28: M | Z28: D | AA28: D | AB28: M | AC28: M | AD28: M | AE28: M | AF28: M | AG28: D | AH28: D | AI28: M | AJ28: M | AK28: M | AL28: M | AM28: M | AN28: D | AO28: D | AP28: M | AQ28: M | AR28: M | AS28: M | AT28: M | AU28: D | AV28: D | AW28: M | AX28: M | AY28: M | AZ28: M | BA28: M | BB28: D | BC28: D | BD28: M | BE28: M | BF28: M | BG28: M | BH28: M | BI28: D | BJ28: D | BK28: M | BL28: M | BM28: M
A29: =Policías!A29 -> 125 | B29: =Policías!B29 -> Antonio Manuel | C29: =Policías!C29 -> Policía | D29: Grupo 5 | E29: D | F29: D | G29: D | H29: D | I29: D | J29: D | K29: M | L29: M | M29: T | N29: T | O29: N | P29: N | Q29: D | R29: D | S29: D | T29: D | U29: D | V29: D | W29: M | X29: M | Y29: T | Z29: T | AA29: N | AB29: N | AC29: D | AD29: D | AE29: D | AF29: D | AG29: D | AH29: D | AI29: M
A30: =Policías!A30 -> 126 | B30: =Policías!B30 -> Daniel | C30: =Policías!C30 -> Policía | D30: Grupo 4 | E30: T | F30: T | G30: N | H30: N | I30: D | J30: D | K30: D | L30: D | M30: D | N30: D | O30: M | P30: M | Q30: T | R30: T | S30: N | T30: N | U30: D | V30: D | W30: D | X30: D | Y30: D | Z30: D | AA30: M | AB30: M | AC30: T | AD30: T | AE30: N | AF30: N | AG30: D | AH30: D | AI30: D
A31: =Policías!A31 -> 127 | B31: =Policías!B31 -> Marian | C31: =Policías!C31 -> Policía | D31: Grupo 5 | E31: D | F31: D | G31: D | H31: D | I31: D | J31: D | K31: M | L31: M | M31: T | N31: T | O31: N | P31: N | Q31: D | R31: D | S31: D | T31: D | U31: D | V31: D | W31: M | X31: M | Y31: T | Z31: T | AA31: N | AB31: N | AC31: D | AD31: D | AE31: D | AF31: D | AG31: D | AH31: D | AI31: M
A32: =Policías!A32 -> 128 | B32: =Policías!B32 -> Concepción | C32: =Policías!C32 -> Policía | D32: Grupo 6 | E32: N | F32: N | G32: D | H32: D | I32: D | J32: D | K32: D | L32: D | M32: M | N32: M | O32: T | P32: T | Q32: N | R32: N | S32: D | T32: D | U32: D | V32: D | W32: D | X32: D | Y32: M | Z32: M | AA32: T | AB32: T | AC32: N | AD32: N | AE32: D | AF32: D | AG32: D | AH32: D | AI32: D
A33: =Policías!A33 -> 129 | B33: =Policías!B33 -> Francisco | C33: =Policías!C33 -> Policía | D33: Grupo 6 | E33: N | F33: N | G33: D | H33: D | I33: D | J33: D | K33: D | L33: D | M33: M | N33: M | O33: T | P33: T | Q33: N | R33: N | S33: D | T33: D | U33: D | V33: D | W33: D | X33: D | Y33: M | Z33: M | AA33: T | AB33: T | AC33: N | AD33: N | AE33: D | AF33: D | AG33: D | AH33: D | AI33: D
A34: =Policías!A34 -> 130 | B34: =Policías!B34 -> Antonio | C34: =Policías!C34 -> Policía | D34: Grupo 4 | E34: T | F34: T | G34: N | H34: N | I34: D | J34: D | K34: D | L34: D | M34: D | N34: D | O34: M | P34: M | Q34: T | R34: T | S34: N | T34: N | U34: D | V34: D | W34: D | X34: D | Y34: D | Z34: D | AA34: M | AB34: M | AC34: T | AD34: T | AE34: N | AF34: N | AG34: D | AH34: D | AI34: D
A35: =Policías!A35 -> 131 | B35: =Policías!B35 -> Manuel Joaquín | C35: =Policías!C35 -> Policía | D35: Grupo 5 | E35: D | F35: D | G35: D | H35: D | I35: D | J35: D | K35: M | L35: M | M35: T | N35: T | O35: N | P35: N | Q35: D | R35: D | S35: D | T35: D | U35: D | V35: D | W35: M | X35: M | Y35: T | Z35: T | AA35: N | AB35: N | AC35: D | AD35: D | AE35: D | AF35: D | AG35: D | AH35: D | AI35: M
A36: =Policías!A36 -> 132 | B36: =Policías!B36 -> Juan Antonio | C36: =Policías!C36 -> Policía | D36: Grupo 1 | E36: D | F36: D | G36: D | H36: D | I36: M | J36: M | K36: T | L36: T | M36: N | N36: N | O36: D | P36: D | Q36: D | R36: D | S36: D | T36: D | U36: M | V36: M | W36: T | X36: T | Y36: N | Z36: N | AA36: D | AB36: D | AC36: D | AD36: D | AE36: D | AF36: D | AG36: M | AH36: M | AI36: T | AJ36: T | AK36: N | AL36: N | AM36: D | AN36: D | AO36: D | AP36: D | AQ36: D | AR36: D | AS36: M | AT36: M | AU36: T | AV36: T | AW36: N | AX36: N | AY36: D | AZ36: D | BA36: D | BB36: D | BC36: D | BD36: D | BE36: M | BF36: M | BG36: T | BH36: T | BI36: N | BJ36: N | BK36: D | BL36: D | BM36: D
A37: =Policías!A37 -> 133 | B37: =Policías!B37 -> Jose Manuel | C37: =Policías!C37 -> Policía | E37: L | F37: M | G37: M | H37: T | I37: T | J37: N | K37: N | L37: L | M37: L | N37: L | O37: L | P37: L | Q37: M | R37: M | S37: T | T37: T | U37: N | V37: N | W37: L | X37: L | Y37: L | Z37: L | AA37: L | AB37: M | AC37: M | AD37: T | AE37: T | AF37: N | AG37: N | AH37: L | AI37: L
A38: =Policías!A38 -> 134 | B38: =Policías!B38 -> José Antonio | C38: =Policías!C38 -> Policía | D38: Grupo 1 | E38: D | F38: D | G38: D | H38: D | I38: M | J38: M | K38: T | L38: T | M38: N | N38: N | O38: D | P38: D | Q38: D | R38: D | S38: D | T38: D | U38: M | V38: M | W38: T | X38: T | Y38: N | Z38: N | AA38: D | AB38: D | AC38: D | AD38: D | AE38: D | AF38: D | AG38: M | AH38: M | AI38: T | AJ38: T | AK38: N | AL38: N | AM38: D | AN38: D | AO38: D | AP38: D | AQ38: D | AR38: D | AS38: M | AT38: M | AU38: T | AV38: T | AW38: N | AX38: N | AY38: D | AZ38: D | BA38: D | BB38: D | BC38: D | BD38: D | BE38: M | BF38: M | BG38: T | BH38: T | BI38: N | BJ38: N | BK38: D | BL38: D | BM38: D
A39: =Policías!A39 -> 135 | B39: =Policías!B39 -> Yolanda | C39: =Policías!C39 -> Policía | D39: Grupo 4 | E39: T | F39: T | G39: N | H39: N | I39: D | J39: D | K39: D | L39: D | M39: D | N39: D | O39: M | P39: M | Q39: T | R39: T | S39: N | T39: N | U39: D | V39: D | W39: D | X39: D | Y39: D | Z39: D | AA39: M | AB39: M | AC39: T | AD39: T | AE39: N | AF39: N | AG39: D | AH39: D | AI39: D
A40: =Policías!A40 -> 136 | B40: =Policías!B40 -> Narciso | C40: =Policías!C40 -> Policía | D40: Grupo 1 | E40: D | F40: D | G40: D | H40: D | I40: M | J40: M | K40: T | L40: T | M40: N | N40: N | O40: D | P40: D | Q40: D | R40: D | S40: D | T40: D | U40: M | V40: M | W40: T | X40: T | Y40: N | Z40: N | AA40: D | AB40: D | AC40: D | AD40: D | AE40: D | AF40: D | AG40: M | AH40: M | AI40: T | AJ40: T | AK40: N | AL40: N | AM40: D | AN40: D | AO40: D | AP40: D | AQ40: D | AR40: D | AS40: M | AT40: M | AU40: T | AV40: T | AW40: N | AX40: N | AY40: D | AZ40: D | BA40: D | BB40: D | BC40: D | BD40: D | BE40: M | BF40: M | BG40: T | BH40: T | BI40: N | BJ40: N | BK40: D | BL40: D | BM40: D
A41: =Policías!A41 -> 137 | B41: =Policías!B41 -> José Díaz | C41: =Policías!C41 -> Policía | D41: Grupo 6 | E41: N | F41: N | G41: D | H41: D | I41: D | J41: D | K41: D | L41: D | M41: M | N41: M | O41: T | P41: T | Q41: N | R41: N | S41: D | T41: D | U41: D | V41: D | W41: D | X41: D | Y41: M | Z41: M | AA41: T | AB41: T | AC41: N | AD41: N | AE41: D | AF41: D | AG41: D | AH41: D | AI41: D
...

Sheet Historico_Extras
A1: HISTÓRICO GENERAL DE EXTRAS REALIZADOS
A2: Registro de extras consolidados
A4: ID Registro | B4: Fecha Servicio | C4: ID Empleado | D4: Nombre Empleado | E4: Turno Cubierto | F4: Días Extras | G4: Total Acumulado | H4: Motivo / Observaciones
A5: 1001 | B5: 01/08/2026 | C5: 101 | D5: =IF(C5="","",IFERROR(VLOOKUP(C5,Policías!$A$5:$B$63,2,FALSE()),"")) -> Francisca | E5: Mañana | F5: =IF(C5="",0,1) -> 1 | G5: =IF(C5="","",SUMIF($C$5:$C$104,C5,$F$5:$F$104)) -> 2 | H5: Refuerzo por evento local
A6: 1002 | B6: 01/08/2026 | C6: 103 | D6: =IF(C6="","",IFERROR(VLOOKUP(C6,Policías!$A$5:$B$63,2,FALSE()),"")) -> Juan | E6: Tarde | F6: =IF(C6="",0,1) -> 1 | G6: =IF(C6="","",SUMIF($C$5:$C$104,C6,$F$5:$F$104)) -> 1 | H6: Sustitución urgente
A7: 1003 | B7: 02/08/2026 | C7: 101 | D7: =IF(C7="","",IFERROR(VLOOKUP(C7,Policías!$A$5:$B$63,2,FALSE()),"")) -> Francisca | E7: Noche | F7: =IF(C7="",0,1) -> 1 | G7: =IF(C7="","",SUMIF($C$5:$C$104,C7,$F$5:$F$104)) -> 2 | H7: Coordinación nocturna
A8: 1004 | D8: =IF(C8="","",IFERROR(VLOOKUP(C8,Policías!$A$5:$B$63,2,FALSE()),"")) | F8: =IF(C8="",0,1) -> 0 | G8: =IF(C8="","",SUMIF($C$5:$C$104,C8,$F$5:$F$104))
A9: 1005 | D9: =IF(C9="","",IFERROR(VLOOKUP(C9,Policías!$A$5:$B$63,2,FALSE()),"")) | F9: =IF(C9="",0,1) -> 0 | G9: =IF(C9="","",SUMIF($C$5:$C$104,C9,$F$5:$F$104))
A10: 1006 | D10: =IF(C10="","",IFERROR(VLOOKUP(C10,Policías!$A$5:$B$63,2,FALSE()),"")) | F10: =IF(C10="",0,1) -> 0 | G10: =IF(C10="","",SUMIF($C$5:$C$104,C10,$F$5:$F$104))
A11: 1007 | D11: =IF(C11="","",IFERROR(VLOOKUP(C11,Policías!$A$5:$B$63,2,FALSE()),"")) | F11: =IF(C11="",0,1) -> 0 | G11: =IF(C11="","",SUMIF($C$5:$C$104,C11,$F$5:$F$104))
A12: 1008 | D12: =IF(C12="","",IFERROR(VLOOKUP(C12,Policías!$A$5:$B$63,2,FALSE()),"")) | F12: =IF(C12="",0,1) -> 0 | G12: =IF(C12="","",SUMIF($C$5:$C$104,C12,$F$5:$F$104))
A13: 1009 | D13: =IF(C13="","",IFERROR(VLOOKUP(C13,Policías!$A$5:$B$63,2,FALSE()),"")) | F13: =IF(C13="",0,1) -> 0 | G13: =IF(C13="","",SUMIF($C$5:$C$104,C13,$F$5:$F$104))
A14: 1010 | D14: =IF(C14="","",IFERROR(VLOOKUP(C14,Policías!$A$5:$B$63,2,FALSE()),"")) | F14: =IF(C14="",0,1) -> 0 | G14: =IF(C14="","",SUMIF($C$5:$C$104,C14,$F$5:$F$104))
A15: 1011 | D15: =IF(C15="","",IFERROR(VLOOKUP(C15,Policías!$A$5:$B$63,2,FALSE()),"")) | F15: =IF(C15="",0,1) -> 0 | G15: =IF(C15="","",SUMIF($C$5:$C$104,C15,$F$5:$F$104))
A16: 1012 | D16: =IF(C16="","",IFERROR(VLOOKUP(C16,Policías!$A$5:$B$63,2,FALSE()),"")) | F16: =IF(C16="",0,1) -> 0 | G16: =IF(C16="","",SUMIF($C$5:$C$104,C16,$F$5:$F$104))
A17: 1013 | D17: =IF(C17="","",IFERROR(VLOOKUP(C17,Policías!$A$5:$B$63,2,FALSE()),"")) | F17: =IF(C17="",0,1) -> 0 | G17: =IF(C17="","",SUMIF($C$5:$C$104,C17,$F$5:$F$104))
A18: 1014 | D18: =IF(C18="","",IFERROR(VLOOKUP(C18,Policías!$A$5:$B$63,2,FALSE()),"")) | F18: =IF(C18="",0,1) -> 0 | G18: =IF(C18="","",SUMIF($C$5:$C$104,C18,$F$5:$F$104))
A19: 1015 | D19: =IF(C19="","",IFERROR(VLOOKUP(C19,Policías!$A$5:$B$63,2,FALSE()),"")) | F19: =IF(C19="",0,1) -> 0 | G19: =IF(C19="","",SUMIF($C$5:$C$104,C19,$F$5:$F$104))
... A104: 1100 | D104: =IF(C104="","",IFERROR(VLOOKUP(C104,Policías!$A$5:$B$63,2,FALSE()),"")) | F104: =IF(C104="",0,1) -> 0 | G104: =IF(C104="","",SUMIF($C$5:$C$104,C104,$F$5:$F$104))

Sheet Panel_Control
A1: PANEL DE CONTROL Y ESTADO GENERAL DE PLANTILLA DE LA POLICÍA
A4: PARÁMETROS DE CONSULTA GENERAL
A5: Fecha del Servicio en Evaluación: | B5: =VLOOKUP(Asignacion_Inscritos!$C$10,Asignacion_Inscritos!$A$6:$F$8,2,FALSE()) -> 15/08/2026
A6: Estado Requerido: | B6: D
A9: ID Empleado | B9: Nombre y Apellidos | C9: Categoría | D9: Estado Hoy en Cuadrante | E9: Turno Día Anterior | F9: Validación Descanso 24h | G9: Días Extras Acumulados | H9: Estatus Disponibilidad
A10: =Policías!A5 -> 101 | B10: =Policías!B5 -> Francisca | C10: =Policías!C5 -> Inspectora | D10: =INDEX(Cuadrante!$D$5:$AH$63,MATCH(A10,Cuadrante!$A$5:$A$63,0),MATCH($B$5,Cuadrante!$D$4:$AH$4,0)) -> D | E10: =IFERROR(INDEX(Cuadrante!$D$5:$AH$63,MATCH(A10,Cuadrante!$A$5:$A$63,0),MATCH($B$5,Cuadrante!$D$4:$AH$4,0)-1),"N/A") -> M | F10: =IF(E10="N","RESTRINGIDO (Viene de Noche)","APTO") -> APTO | G10: =SUMIF(Historico_Extras!$C$5:$C$104,A10,Historico_Extras!$F$5:$F$104) -> 2 | H10: =IF(OR(D10="VAC",D10="BAJA",D10="AP",D10="HS"),"NO DISPONIBLE ("&D10&")",IF(D10<>"D","DISPONIBLE DOBLANDO",IF(F10="RESTRINGIDO (Viene de Noche)","RESTRINGIDO (Descanso 24h)",IF(G10=0,"PRIORITARIO LIBRE (0 ext)","ELEGIBLE LIBRE ("&G10&" ext)")))) -> ELEGIBLE LIBRE (2 ext)
A11: =Policías!A6 -> 102 | B11: =Policías!B6 -> Manuel | C11: =Policías!C6 -> Subinspector | D11: =INDEX(Cuadrante!$D$5:$AH$63,MATCH(A11,Cuadrante!$A$5:$A$63,0),MATCH($B$5,Cuadrante!$D$4:$AH$4,0)) -> D | E11: =IFERROR(INDEX(Cuadrante!$D$5:$AH$63,MATCH(A11,Cuadrante!$A$5:$A$63,0),MATCH($B$5,Cuadrante!$D$4:$AH$4,0)-1),"N/A") -> M | F11: =IF(E11="N","RESTRINGIDO (Viene de Noche)","APTO") -> APTO | G11: =SUMIF(Historico_Extras!$C$5:$C$104,A11,Historico_Extras!$F$5:$F$104) -> 0 | H11: =IF(OR(D11="VAC",D11="BAJA",D11="AP",D11="HS"),"NO DISPONIBLE ("&D11&")",IF(D11<>"D","DISPONIBLE DOBLANDO",IF(F11="RESTRINGIDO (Viene de Noche)","RESTRINGIDO (Descanso 24h)",IF(G11=0,"PRIORITARIO LIBRE (0 ext)","ELEGIBLE LIBRE ("&G11&" ext)")))) -> PRIORITARIO LIBRE (0 ext)
A12: =Policías!A7 -> 103 | B12: =Policías!B7 -> Juan | C12: =Policías!C7 -> Oficial Policía | D12: =INDEX(Cuadrante!$D$5:$AH$63,MATCH(A12,Cuadrante!$A$5:$A$63,0),MATCH($B$5,Cuadrante!$D$4:$AH$4,0)) -> M | E12: =IFERROR(INDEX(Cuadrante!$D$5:$AH$63,MATCH(A12,Cuadrante!$A$5:$A$63,0),MATCH($B$5,Cuadrante!$D$4:$AH$4,0)-1),"N/A") -> M | F12: =IF(E12="N","RESTRINGIDO (Viene de Noche)","APTO") -> APTO | G12: =SUMIF(Historico_Extras!$C$5:$C$104,A12,Historico_Extras!$F$5:$F$104) -> 1 | H12: =IF(OR(D12="VAC",D12="BAJA",D12="AP",D12="HS"),"NO DISPONIBLE ("&D12&")",IF(D12<>"D","DISPONIBLE DOBLANDO",IF(F12="RESTRINGIDO (Viene de Noche)","RESTRINGIDO (Descanso 24h)",IF(G12=0,"PRIORITARIO LIBRE (0 ext)","ELEGIBLE LIBRE ("&G12&" ext)")))) -> DISPONIBLE DOBLANDO
A13: =Policías!A8 -> 104 | B13: =Policías!B8 -> Diego | C13: =Policías!C8 -> Oficial Policía | D13: =INDEX(Cuadrante!$D$5:$AH$63,MATCH(A13,Cuadrante!$A$5:$A$63,0),MATCH($B$5,Cuadrante!$D$4:$AH$4,0)) -> BAJA | E13: =IFERROR(INDEX(Cuadrante!$D$5:$AH$63,MATCH(A13,Cuadrante!$A$5:$A$63,0),MATCH($B$5,Cuadrante!$D$4:$AH$4,0)-1),"N/A") -> BAJA | F13: =IF(E13="N","RESTRINGIDO (Viene de Noche)","APTO") -> APTO | G13: =SUMIF(Historico_Extras!$C$5:$C$104,A13,Historico_Extras!$F$5:$F$104) -> 0 | H13: =IF(OR(D13="VAC",D13="BAJA",D13="AP",D13="HS"),"NO DISPONIBLE ("&D13&")",IF(D13<>"D","DISPONIBLE DOBLANDO",IF(F13="RESTRINGIDO (Viene de Noche)","RESTRINGIDO (Descanso 24h)",IF(G13=0,"PRIORITARIO LIBRE (0 ext)","ELEGIBLE LIBRE ("&G13&" ext)")))) -> NO DISPONIBLE (BAJA)
A14: =Policías!A9 -> 105 | B14: =Policías!B9 -> Adrián | C14: =Policías!C9 -> Oficial Policía | D14: =INDEX(Cuadrante!$D$5:$AH$63,MATCH(A14,Cuadrante!$A$5:$A$63,0),MATCH($B$5,Cuadrante!$D$4:$AH$4,0)) -> D | E14: =IFERROR(INDEX(Cuadrante!$D$5:$AH$63,MATCH(A14,Cuadrante!$A$5:$A$63,0),MATCH($B$5,Cuadrante!$D$4:$AH$4,0)-1),"N/A") -> D | F14: =IF(E14="N","RESTRINGIDO (Viene de Noche)","APTO") -> APTO | G14: =SUMIF(Historico_Extras!$C$5:$C$104,A14,Historico_Extras!$F$5:$F$104) -> 0 | H14: =IF(OR(D14="VAC",D14="BAJA",D14="AP",D14="HS"),"NO DISPONIBLE ("&D14&")",IF(D14<>"D","DISPONIBLE DOBLANDO",IF(F14="RESTRINGIDO (Viene de Noche)","RESTRINGIDO (Descanso 24h)",IF(G14=0,"PRIORITARIO LIBRE (0 ext)","ELEGIBLE LIBRE ("&G14&" ext)")))) -> PRIORITARIO LIBRE (0 ext)
A15: =Policías!A10 -> 106 | B15: =Policías!B10 -> Juan Rafael | C15: =Policías!C10 -> Oficial Policía | D15: =INDEX(Cuadrante!$D$5:$AH$63,MATCH(A15,Cuadrante!$A$5:$A$63,0),MATCH($B$5,Cuadrante!$D$4:$AH$4,0)) -> T | E15: =IFERROR(INDEX(Cuadrante!$D$5:$AH$63,MATCH(A15,Cuadrante!$A$5:$A$63,0),MATCH($B$5,Cuadrante!$D$4:$AH$4,0)-1),"N/A") -> M | F15: =IF(E15="N","RESTRINGIDO (Viene de Noche)","APTO") -> APTO | G15: =SUMIF(Historico_Extras!$C$5:$C$104,A15,Historico_Extras!$F$5:$F$104) -> 0 | H15: =IF(OR(D15="VAC",D15="BAJA",D15="AP",D15="HS"),"NO DISPONIBLE ("&D15&")",IF(D15<>"D","DISPONIBLE DOBLANDO",IF(F15="RESTRINGIDO (Viene de Noche)","RESTRINGIDO (Descanso 24h)",IF(G15=0,"PRIORITARIO LIBRE (0 ext)","ELEGIBLE LIBRE ("&G15&" ext)")))) -> DISPONIBLE DOBLANDO
A16: =Policías!A11 -> 107 | B16: =Policías!B11 -> Matías | C16: =Policías!C11 -> Oficial Policía | D16: =INDEX(Cuadrante!$D$5:$AH$63,MATCH(A16,Cuadrante!$A$5:$A$63,0),MATCH($B$5,Cuadrante!$D$4:$AH$4,0)) -> D | E16: =IFERROR(INDEX(Cuadrante!$D$5:$AH$63,MATCH(A16,Cuadrante!$A$5:$A$63,0),MATCH($B$5,Cuadrante!$D$4:$AH$4,0)-1),"N/A") -> D | F16: =IF(E16="N","RESTRINGIDO (Viene de Noche)","APTO") -> APTO | G16: =SUMIF(Historico_Extras!$C$5:$C$104,A16,Historico_Extras!$F$5:$F$104) -> 0 | H16: =IF(OR(D16="VAC",D16="BAJA",D16="AP",D16="HS"),"NO DISPONIBLE ("&D16&")",IF(D16<>"D","DISPONIBLE DOBLANDO",IF(F16="RESTRINGIDO (Viene de Noche)","RESTRINGIDO (Descanso 24h)",IF(G16=0,"PRIORITARIO LIBRE (0 ext)","ELEGIBLE LIBRE ("&G16&" ext)")))) -> PRIORITARIO LIBRE (0 ext)
A17: =Policías!A12 -> 108 | B17: =Policías!B12 -> Manuel 2 | C17: =Policías!C12 -> Oficial Policía | D17: =INDEX(Cuadrante!$D$5:$AH$63,MATCH(A17,Cuadrante!$A$5:$A$63,0),MATCH($B$5,Cuadrante!$D$4:$AH$4,0)) -> D | E17: =IFERROR(INDEX(Cuadrante!$D$5:$AH$63,MATCH(A17,Cuadrante!$A$5:$A$63,0),MATCH($B$5,Cuadrante!$D$4:$AH$4,0)-1),"N/A") -> D | F17: =IF(E17="N","RESTRINGIDO (Viene de Noche)","APTO") -> APTO | G17: =SUMIF(Historico_Extras!$C$5:$C$104,A17,Historico_Extras!$F$5:$F$104) -> 0 | H17: =IF(OR(D17="VAC",D17="BAJA",D17="AP",D17="HS"),"NO DISPONIBLE ("&D17&")",IF(D17<>"D","DISPONIBLE DOBLANDO",IF(F17="RESTRINGIDO (Viene de Noche)","RESTRINGIDO (Descanso 24h)",IF(G17=0,"PRIORITARIO LIBRE (0 ext)","ELEGIBLE LIBRE ("&G17&" ext)")))) -> PRIORITARIO LIBRE (0 ext)
A18: =Policías!A13 -> 109 | B18: =Policías!B13 -> Manuel 3 | C18: =Policías!C13 -> Oficial Policía Organizativo | D18: =INDEX(Cuadrante!$D$5:$AH$63,MATCH(A18,Cuadrante!$A$5:$A$63,0),MATCH($B$5,Cuadrante!$D$4:$AH$4,0)) -> D | E18: =IFERROR(INDEX(Cuadrante!$D$5:$AH$63,MATCH(A18,Cuadrante!$A$5:$A$63,0),MATCH($B$5,Cuadrante!$D$4:$AH$4,0)-1),"N/A") -> M | F18: =IF(E18="N","RESTRINGIDO (Viene de Noche)","APTO") -> APTO | G18: =SUMIF(Historico_Extras!$C$5:$C$104,A18,Historico_Extras!$F$5:$F$104) -> 0 | H18: =IF(OR(D18="VAC",D18="BAJA",D18="AP",D18="HS"),"NO DISPONIBLE ("&D18&")",IF(D18<>"D","DISPONIBLE DOBLANDO",IF(F18="RESTRINGIDO (Viene de Noche)","RESTRINGIDO (Descanso 24h)",IF(G18=0,"PRIORITARIO LIBRE (0 ext)","ELEGIBLE LIBRE ("&G18&" ext)")))) -> PRIORITARIO LIBRE (0 ext)
A19: =Policías!A14 -> 110 | B19: =Policías!B14 -> Julián | C19: =Policías!C14 -> Policía | D19: =INDEX(Cuadrante!$D$5:$AH$63,MATCH(A19,Cuadrante!$A$5:$A$63,0),MATCH($B$5,Cuadrante!$D$4:$AH$4,0)) -> D | E19: =IFERROR(INDEX(Cuadrante!$D$5:$AH$63,MATCH(A19,Cuadrante!$A$5:$A$63,0),MATCH($B$5,Cuadrante!$D$4:$AH$4,0)-1),"N/A") -> M | F19: =IF(E19="N","RESTRINGIDO (Viene de Noche)","APTO") -> APTO | G19: =SUMIF(Historico_Extras!$C$5:$C$104,A19,Historico_Extras!$F$5:$F$104) -> 0 | H19: =IF(OR(D19="VAC",D19="BAJA",D19="AP",D19="HS"),"NO DISPONIBLE ("&D19&")",IF(D19<>"D","DISPONIBLE DOBLANDO",IF(F19="RESTRINGIDO (Viene de Noche)","RESTRINGIDO (Descanso 24h)",IF(G19=0,"PRIORITARIO LIBRE (0 ext)","ELEGIBLE LIBRE ("&G19&" ext)")))) -> PRIORITARIO LIBRE (0 ext)
A20: =Policías!A15 -> 111 | B20: =Policías!B15 -> Rocío | C20: =Policías!C15 -> Policía | D20: =INDEX(Cuadrante!$D$5:$AH$63,MATCH(A20,Cuadrante!$A$5:$A$63,0),MATCH($B$5,Cuadrante!$D$4:$AH$4,0)) -> M | E20: =IFERROR(INDEX(Cuadrante!$D$5:$AH$63,MATCH(A20,Cuadrante!$A$5:$A$63,0),MATCH($B$5,Cuadrante!$D$4:$AH$4,0)-1),"N/A") -> M | F20: =IF(E20="N","RESTRINGIDO (Viene de Noche)","APTO") -> APTO | G20: =SUMIF(Historico_Extras!$C$5:$C$104,A20,Historico_Extras!$F$5:$F$104) -> 0 | H20: =IF(OR(D20="VAC",D20="BAJA",D20="AP",D20="HS"),"NO DISPONIBLE ("&D20&")",IF(D20<>"D","DISPONIBLE DOBLANDO",IF(F20="RESTRINGIDO (Viene de Noche)","RESTRINGIDO (Descanso 24h)",IF(G20=0,"PRIORITARIO LIBRE (0 ext)","ELEGIBLE LIBRE ("&G20&" ext)")))) -> DISPONIBLE DOBLANDO
A21: =Policías!A16 -> 112 | B21: =Policías!B16 -> Juan Jesús | C21: =Policías!C16 -> Policía | D21: =INDEX(Cuadrante!$D$5:$AH$63,MATCH(A21,Cuadrante!$A$5:$A$63,0),MATCH($B$5,Cuadrante!$D$4:$AH$4,0)) -> D | E21: =IFERROR(INDEX(Cuadrante!$D$5:$AH$63,MATCH(A21,Cuadrante!$A$5:$A$63,0),MATCH($B$5,Cuadrante!$D$4:$AH$4,0)-1),"N/A") -> D | F21: =IF(E21="N","RESTRINGIDO (Viene de Noche)","APTO") -> APTO | G21: =SUMIF(Historico_Extras!$C$5:$C$104,A21,Historico_Extras!$F$5:$F$104) -> 0 | H21: =IF(OR(D21="VAC",D21="BAJA",D21="AP",D21="HS"),"NO DISPONIBLE ("&D21&")",IF(D21<>"D","DISPONIBLE DOBLANDO",IF(F21="RESTRINGIDO (Viene de Noche)","RESTRINGIDO (Descanso 24h)",IF(G21=0,"PRIORITARIO LIBRE (0 ext)","ELEGIBLE LIBRE ("&G21&" ext)")))) -> PRIORITARIO LIBRE (0 ext)
... A68: =Policías!A63 -> 159 | B68: =Policías!B63 -> Muriel | C68: =Policías!C63 -> Policía | D68: =INDEX(Cuadrante!$D$5:$AH$63,MATCH(A68,Cuadrante!$A$5:$A$63,0),MATCH($B$5,Cuadrante!$D$4:$AH$4,0)) -> T | E68: =IFERROR(INDEX(Cuadrante!$D$5:$AH$63,MATCH(A68,Cuadrante!$A$5:$A$63,0),MATCH($B$5,Cuadrante!$D$4:$AH$4,0)-1),"N/A") -> M | F68: =IF(E68="N","RESTRINGIDO (Viene de Noche)","APTO") -> APTO | G68: =SUMIF(Historico_Extras!$C$5:$C$104,A68,Historico_Extras!$F$5:$F$104) -> 0 | H68: =IF(OR(D68="VAC",D68="BAJA",D68="AP",D68="HS"),"NO DISPONIBLE ("&D68&")",IF(D68<>"D","DISPONIBLE DOBLANDO",IF(F68="RESTRINGIDO (Viene de Noche)","RESTRINGIDO (Descanso 24h)",IF(G68=0,"PRIORITARIO LIBRE (0 ext)","ELEGIBLE LIBRE ("&G68&" ext)")))) -> DISPONIBLE DOBLANDO

Sheet Asignacion_Inscritos
A1: SISTEMA DE ADJUDICACIÓN DE EXTRAS A INSCRITOS
A2: 1. Define las plazas | 2. Apunta voluntarios inscritos | 3. Adjudica primero a Libres (D) por menos extras y luego a Dobles Turnos (excluyendo Noche->Mañana, VAC, BAJA, AP, HS).
A4: 1. OFERTAS DE EXTRAS PUBLICADAS POR JEFATURA
A5: Nº Oferta | B5: Fecha del Extra | C5: Turno Requerido | D5: Puesto / Categoría | E5: Plazas / Extras Solicitados | F5: Motivo / Departamento
A6: 1 | B6: 15/08/2026 | C6: Mañana | D6: Oficial 1ª | E6: 2 | F6: Jefatura - Refuerzo Fiestas (2 plazas)
A7: 2 | B7: 15/08/2026 | C7: Tarde | D7: Oficial 2ª | E7: 1 | F7: Servicios Técnicos (1 plaza)
A8: 3 | B8: 16/08/2026 | C8: Noche | D8: Coordinador | E8: 3 | F8: Operativo Especial (3 plazas)
A10: Nº DE OFERTA A EVALUAR Y ADJUDICAR: | C10: 1 | E10: PLAZAS EXTRAS SOLICITADAS: | G10: =VLOOKUP($C$10,$A$6:$F$8,5,FALSE()) -> 2
A12: 2. REGISTRO DE TRABAJADORES APUNTADOS / VOLUNTARIOS Y ADJUDICACIÓN DE PLAZAS
A13: ID Voluntario Apuntado | B13: Nombre y Apellidos | C13: Categoría | D13: Estado Cuadrante (Día Extra) | E13: Turno Día Anterior | F13: Validación Descanso 24h | G13: Días Extras Acumulados | H13: Score Prioridad | I13: Ranking de Equidad | J13: ESTADO ADJUDICACIÓN
A14: 101 | B14: =IF(A14="","",IFERROR(VLOOKUP(A14,Policías!$A$5:$B$63,2,FALSE()),"")) -> Francisca | C14: =IF(A14="","",IFERROR(VLOOKUP(A14,Policías!$A$5:$C$63,3,FALSE()),"")) -> Inspectora | D14: =IF(A14="","",INDEX(Cuadrante!$D$5:$AH$63,MATCH(A14,Cuadrante!$A$5:$A$63,0),MATCH(VLOOKUP($C$10,$A$6:$F$8,2,FALSE()),Cuadrante!$D$4:$AH$4,0))) -> D | E14: =IF(A14="","",IFERROR(INDEX(Cuadrante!$D$5:$AH$63,MATCH(A14,Cuadrante!$A$5:$A$63,0),MATCH(VLOOKUP($C$10,$A$6:$F$8,2,FALSE()),Cuadrante!$D$4:$AH$4,0)-1),"N/A")) -> M | F14: =IF(A14="","",IF(OR(AND(E14="N",VLOOKUP($C$10,$A$6:$F$8,3,FALSE())="Mañana"),AND(D14="N",VLOOKUP($C$10,$A$6:$F$8,3,FALSE())="Mañana")),"RESTRINGIDO (Noche a Mañana)","APTO")) -> APTO | G14: =IF(A14="","",SUMIF(Historico_Extras!$C$5:$C$104,A14,Historico_Extras!$F$5:$F$104)) -> 2 | H14: =IF(A14="","",IF(OR(F14<>"APTO",D14="VAC",D14="BAJA",D14="AP",D14="HS"),99999,IF(D14="D",G14*1000+ROW(),50000+G14*1000+ROW()))) -> 2014 | I14: =IF(OR(A14="",H14=99999),"",RANK(H14,$H$14:$H$33,1)) -> 7 | J14: =IF(A14="","",IF(OR(D14="VAC",D14="BAJA",D14="AP",D14="HS"),"NO DISPONIBLE ("&D14&")",IF(F14<>"APTO","RESTRINGIDO (Noche a Mañana)",IF(AND(I14<>"",I14<=$G$10),IF(D14="D","¡ADJUDICADO LIBRE! (Plaza "&I14&")","¡ADJUDICADO DOBLANDO! (Plaza "&I14&")"),IF(D14="D","Inscrito Libre ("&G14&" ext)","Inscrito Doblado ("&G14&" ext)"))))) -> Inscrito Libre (2 ext)
A15: 102 | B15: =IF(A15="","",IFERROR(VLOOKUP(A15,Policías!$A$5:$B$63,2,FALSE()),"")) -> Manuel | C15: =IF(A15="","",IFERROR(VLOOKUP(A15,Policías!$A$5:$C$63,3,FALSE()),"")) -> Subinspector | D15: =IF(A15="","",INDEX(Cuadrante!$D$5:$AH$63,MATCH(A15,Cuadrante!$A$5:$A$63,0),MATCH(VLOOKUP($C$10,$A$6:$F$8,2,FALSE()),Cuadrante!$D$4:$AH$4,0))) -> D | E15: =IF(A15="","",IFERROR(INDEX(Cuadrante!$D$5:$AH$63,MATCH(A15,Cuadrante!$A$5:$A$63,0),MATCH(VLOOKUP($C$10,$A$6:$F$8,2,FALSE()),Cuadrante!$D$4:$AH$4,0)-1),"N/A")) -> M | F15: =IF(A15="","",IF(OR(AND(E15="N",VLOOKUP($C$10,$A$6:$F$8,3,FALSE())="Mañana"),AND(D15="N",VLOOKUP($C$10,$A$6:$F$8,3,FALSE())="Mañana")),"RESTRINGIDO (Noche a Mañana)","APTO")) -> APTO | G15: =IF(A15="","",SUMIF(Historico_Extras!$C$5:$C$104,A15,Historico_Extras!$F$5:$F$104)) -> 0 | H15: =IF(A15="","",IF(OR(F15<>"APTO",D15="VAC",D15="BAJA",D15="AP",D15="HS"),99999,IF(D15="D",G15*1000+ROW(),50000+G15*1000+ROW()))) -> 15 | I15: =IF(OR(A15="",H15=99999),"",RANK(H15,$H$14:$H$33,1)) -> 1 | J15: =IF(A15="","",IF(OR(D15="VAC",D15="BAJA",D15="AP",D15="HS"),"NO DISPONIBLE ("&D15&")",IF(F15<>"APTO","RESTRINGIDO (Noche a Mañana)",IF(AND(I15<>"",I15<=$G$10),IF(D15="D","¡ADJUDICADO LIBRE! (Plaza "&I15&")","¡ADJUDICADO DOBLANDO! (Plaza "&I15&")"),IF(D15="D","Inscrito Libre ("&G15&" ext)","Inscrito Doblado ("&G15&" ext)"))))) -> ¡ADJUDICADO LIBRE! (Plaza 1)
A16: 105 | B16: =IF(A16="","",IFERROR(VLOOKUP(A16,Policías!$A$5:$B$63,2,FALSE()),"")) -> Adrián | C16: =IF(A16="","",IFERROR(VLOOKUP(A16,Policías!$A$5:$C$63,3,FALSE()),"")) -> Oficial Policía | D16: =IF(A16="","",INDEX(Cuadrante!$D$5:$AH$63,MATCH(A16,Cuadrante!$A$5:$A$63,0),MATCH(VLOOKUP($C$10,$A$6:$F$8,2,FALSE()),Cuadrante!$D$4:$AH$4,0))) -> D | E16: =IF(A16="","",IFERROR(INDEX(Cuadrante!$D$5:$AH$63,MATCH(A16,Cuadrante!$A$5:$A$63,0),MATCH(VLOOKUP($C$10,$A$6:$F$8,2,FALSE()),Cuadrante!$D$4:$AH$4,0)-1),"N/A")) -> D | F16: =IF(A16="","",IF(OR(AND(E16="N",VLOOKUP($C$10,$A$6:$F$8,3,FALSE())="Mañana"),AND(D16="N",VLOOKUP($C$10,$A$6:$F$8,3,FALSE())="Mañana")),"RESTRINGIDO (Noche a Mañana)","APTO")) -> APTO | G16: =IF(A16="","",SUMIF(Historico_Extras!$C$5:$C$104,A16,Historico_Extras!$F$5:$F$104)) -> 0 | H16: =IF(A16="","",IF(OR(F16<>"APTO",D16="VAC",D16="BAJA",D16="AP",D16="HS"),99999,IF(D16="D",G16*1000+ROW(),50000+G16*1000+ROW()))) -> 16 | I16: =IF(OR(A16="",H16=99999),"",RANK(H16,$H$14:$H$33,1)) -> 2 | J16: =IF(A16="","",IF(OR(D16="VAC",D16="BAJA",D16="AP",D16="HS"),"NO DISPONIBLE ("&D16&")",IF(F16<>"APTO","RESTRINGIDO (Noche a Mañana)",IF(AND(I16<>"",I16<=$G$10),IF(D16="D","¡ADJUDICADO LIBRE! (Plaza "&I16&")","¡ADJUDICADO DOBLANDO! (Plaza "&I16&")"),IF(D16="D","Inscrito Libre ("&G16&" ext)","Inscrito Doblado ("&G16&" ext)"))))) -> ¡ADJUDICADO LIBRE! (Plaza 2)
A17: 108 | B17: =IF(A17="","",IFERROR(VLOOKUP(A17,Policías!$A$5:$B$63,2,FALSE()),"")) -> Manuel 2 | C17: =IF(A17="","",IFERROR(VLOOKUP(A17,Policías!$A$5:$C$63,3,FALSE()),"")) -> Oficial Policía | D17: =IF(A17="","",INDEX(Cuadrante!$D$5:$AH$63,MATCH(A17,Cuadrante!$A$5:$A$63,0),MATCH(VLOOKUP($C$10,$A$6:$F$8,2,FALSE()),Cuadrante!$D$4:$AH$4,0))) -> D | E17: =IF(A17="","",IFERROR(INDEX(Cuadrante!$D$5:$AH$63,MATCH(A17,Cuadrante!$A$5:$A$63,0),MATCH(VLOOKUP($C$10,$A$6:$F$8,2,FALSE()),Cuadrante!$D$4:$AH$4,0)-1),"N/A")) -> D | F17: =IF(A17="","",IF(OR(AND(E17="N",VLOOKUP($C$10,$A$6:$F$8,3,FALSE())="Mañana"),AND(D17="N",VLOOKUP($C$10,$A$6:$F$8,3,FALSE())="Mañana")),"RESTRINGIDO (Noche a Mañana)","APTO")) -> APTO | G17: =IF(A17="","",SUMIF(Historico_Extras!$C$5:$C$104,A17,Historico_Extras!$F$5:$F$104)) -> 0 | H17: =IF(A17="","",IF(OR(F17<>"APTO",D17="VAC",D17="BAJA",D17="AP",D17="HS"),99999,IF(D17="D",G17*1000+ROW(),50000+G17*1000+ROW()))) -> 17 | I17: =IF(OR(A17="",H17=99999),"",RANK(H17,$H$14:$H$33,1)) -> 3 | J17: =IF(A17="","",IF(OR(D17="VAC",D17="BAJA",D17="AP",D17="HS"),"NO DISPONIBLE ("&D17&")",IF(F17<>"APTO","RESTRINGIDO (Noche a Mañana)",IF(AND(I17<>"",I17<=$G$10),IF(D17="D","¡ADJUDICADO LIBRE! (Plaza "&I17&")","¡ADJUDICADO DOBLANDO! (Plaza "&I17&")"),IF(D17="D","Inscrito Libre ("&G17&" ext)","Inscrito Doblado ("&G17&" ext)"))))) -> Inscrito Libre (0 ext)
A18: 110 | B18: =IF(A18="","",IFERROR(VLOOKUP(A18,Policías!$A$5:$B$63,2,FALSE()),"")) -> Julián | C18: =IF(A18="","",IFERROR(VLOOKUP(A18,Policías!$A$5:$C$63,3,FALSE()),"")) -> Policía | D18: =IF(A18="","",INDEX(Cuadrante!$D$5:$AH$63,MATCH(A18,Cuadrante!$A$5:$A$63,0),MATCH(VLOOKUP($C$10,$A$6:$F$8,2,FALSE()),Cuadrante!$D$4:$AH$4,0))) -> D | E18: =IF(A18="","",IFERROR(INDEX(Cuadrante!$D$5:$AH$63,MATCH(A18,Cuadrante!$A$5:$A$63,0),MATCH(VLOOKUP($C$10,$A$6:$F$8,2,FALSE()),Cuadrante!$D$4:$AH$4,0)-1),"N/A")) -> M | F18: =IF(A18="","",IF(OR(AND(E18="N",VLOOKUP($C$10,$A$6:$F$8,3,FALSE())="Mañana"),AND(D18="N",VLOOKUP($C$10,$A$6:$F$8,3,FALSE())="Mañana")),"RESTRINGIDO (Noche a Mañana)","APTO")) -> APTO | G18: =IF(A18="","",SUMIF(Historico_Extras!$C$5:$C$104,A18,Historico_Extras!$F$5:$F$104)) -> 0 | H18: =IF(A18="","",IF(OR(F18<>"APTO",D18="VAC",D18="BAJA",D18="AP",D18="HS"),99999,IF(D18="D",G18*1000+ROW(),50000+G18*1000+ROW()))) -> 18 | I18: =IF(OR(A18="",H18=99999),"",RANK(H18,$H$14:$H$33,1)) -> 4 | J18: =IF(A18="","",IF(OR(D18="VAC",D18="BAJA",D18="AP",D18="HS"),"NO DISPONIBLE ("&D18&")",IF(F18<>"APTO","RESTRINGIDO (Noche a Mañana)",IF(AND(I18<>"",I18<=$G$10),IF(D18="D","¡ADJUDICADO LIBRE! (Plaza "&I18&")","¡ADJUDICADO DOBLANDO! (Plaza "&I18&")"),IF(D18="D","Inscrito Libre ("&G18&" ext)","Inscrito Doblado ("&G18&" ext)"))))) -> Inscrito Libre (0 ext)
A19: 112 | B19: =IF(A19="","",IFERROR(VLOOKUP(A19,Policías!$A$5:$B$63,2,FALSE()),"")) -> Juan Jesús | C19: =IF(A19="","",IFERROR(VLOOKUP(A19,Policías!$A$5:$C$63,3,FALSE()),"")) -> Policía | D19: =IF(A19="","",INDEX(Cuadrante!$D$5:$AH$63,MATCH(A19,Cuadrante!$A$5:$A$63,0),MATCH(VLOOKUP($C$10,$A$6:$F$8,2,FALSE()),Cuadrante!$D$4:$AH$4,0))) -> D | E19: =IF(A19="","",IFERROR(INDEX(Cuadrante!$D$5:$AH$63,MATCH(A19,Cuadrante!$A$5:$A$63,0),MATCH(VLOOKUP($C$10,$A$6:$F$8,2,FALSE()),Cuadrante!$D$4:$AH$4,0)-1),"N/A")) -> D | F19: =IF(A19="","",IF(OR(AND(E19="N",VLOOKUP($C$10,$A$6:$F$8,3,FALSE())="Mañana"),AND(D19="N",VLOOKUP($C$10,$A$6:$F$8,3,FALSE())="Mañana")),"RESTRINGIDO (Noche a Mañana)","APTO")) -> APTO | G19: =IF(A19="","",SUMIF(Historico_Extras!$C$5:$C$104,A19,Historico_Extras!$F$5:$F$104)) -> 0 | H19: =IF(A19="","",IF(OR(F19<>"APTO",D19="VAC",D19="BAJA",D19="AP",D19="HS"),99999,IF(D19="D",G19*1000+ROW(),50000+G19*1000+ROW()))) -> 19 | I19: =IF(OR(A19="",H19=99999),"",RANK(H19,$H$14:$H$33,1)) -> 5 | J19: =IF(A19="","",IF(OR(D19="VAC",D19="BAJA",D19="AP",D19="HS"),"NO DISPONIBLE ("&D19&")",IF(F19<>"APTO","RESTRINGIDO (Noche a Mañana)",IF(AND(I19<>"",I19<=$G$10),IF(D19="D","¡ADJUDICADO LIBRE! (Plaza "&I19&")","¡ADJUDICADO DOBLANDO! (Plaza "&I19&")"),IF(D19="D","Inscrito Libre ("&G19&" ext)","Inscrito Doblado ("&G19&" ext)"))))) -> Inscrito Libre (0 ext)
A20: 115 | B20: =IF(A20="","",IFERROR(VLOOKUP(A20,Policías!$A$5:$B$63,2,FALSE()),"")) -> Martín Francisco | C20: =IF(A20="","",IFERROR(VLOOKUP(A20,Policías!$A$5:$C$63,3,FALSE()),"")) -> Policía | D20: =IF(A20="","",INDEX(Cuadrante!$D$5:$AH$63,MATCH(A20,Cuadrante!$A$5:$A$63,0),MATCH(VLOOKUP($C$10,$A$6:$F$8,2,FALSE()),Cuadrante!$D$4:$AH$4,0))) -> D | E20: =IF(A20="","",IFERROR(INDEX(Cuadrante!$D$5:$AH$63,MATCH(A20,Cuadrante!$A$5:$A$63,0),MATCH(VLOOKUP($C$10,$A$6:$F$8,2,FALSE()),Cuadrante!$D$4:$AH$4,0)-1),"N/A")) -> N | F20: =IF(A20="","",IF(OR(AND(E20="N",VLOOKUP($C$10,$A$6:$F$8,3,FALSE())="Mañana"),AND(D20="N",VLOOKUP($C$10,$A$6:$F$8,3,FALSE())="Mañana")),"RESTRINGIDO (Noche a Mañana)","APTO")) -> RESTRINGIDO (Noche a Mañana) | G20: =IF(A20="","",SUMIF(Historico_Extras!$C$5:$C$104,A20,Historico_Extras!$F$5:$F$104)) -> 0 | H20: =IF(A20="","",IF(OR(F20<>"APTO",D20="VAC",D20="BAJA",D20="AP",D20="HS"),99999,IF(D20="D",G20*1000+ROW(),50000+G20*1000+ROW()))) -> 99999 | I20: =IF(OR(A20="",H20=99999),"",RANK(H20,$H$14:$H$33,1)) | J20: =IF(A20="","",IF(OR(D20="VAC",D20="BAJA",D20="AP",D20="HS"),"NO DISPONIBLE ("&D20&")",IF(F20<>"APTO","RESTRINGIDO (Noche a Mañana)",IF(AND(I20<>"",I20<=$G$10),IF(D20="D","¡ADJUDICADO LIBRE! (Plaza "&I20&")","¡ADJUDICADO DOBLANDO! (Plaza "&I20&")"),IF(D20="D","Inscrito Libre ("&G20&" ext)","Inscrito Doblado ("&G20&" ext)"))))) -> RESTRINGIDO (Noche a Mañana)
A21: 120 | B21: =IF(A21="","",IFERROR(VLOOKUP(A21,Policías!$A$5:$B$63,2,FALSE()),"")) -> Jose Antonio | C21: =IF(A21="","",IFERROR(VLOOKUP(A21,Policías!$A$5:$C$63,3,FALSE()),"")) -> Policía | D21: =IF(A21="","",INDEX(Cuadrante!$D$5:$AH$63,MATCH(A21,Cuadrante!$A$5:$A$63,0),MATCH(VLOOKUP($C$10,$A$6:$F$8,2,FALSE()),Cuadrante!$D$4:$AH$4,0))) -> D | E21: =IF(A21="","",IFERROR(INDEX(Cuadrante!$D$5:$AH$63,MATCH(A21,Cuadrante!$A$5:$A$63,0),MATCH(VLOOKUP($C$10,$A$6:$F$8,2,FALSE()),Cuadrante!$D$4:$AH$4,0)-1),"N/A")) -> D | F21: =IF(A21="","",IF(OR(AND(E21="N",VLOOKUP($C$10,$A$6:$F$8,3,FALSE())="Mañana"),AND(D21="N",VLOOKUP($C$10,$A$6:$F$8,3,FALSE())="Mañana")),"RESTRINGIDO (Noche a Mañana)","APTO")) -> APTO | G21: =IF(A21="","",SUMIF(Historico_Extras!$C$5:$C$104,A21,Historico_Extras!$F$5:$F$104)) -> 0 | H21: =IF(A21="","",IF(OR(F21<>"APTO",D21="VAC",D21="BAJA",D21="AP",D21="HS"),99999,IF(D21="D",G21*1000+ROW(),50000+G21*1000+ROW()))) -> 21 | I21: =IF(OR(A21="",H21=99999),"",RANK(H21,$H$14:$H$33,1)) -> 6 | J21: =IF(A21="","",IF(OR(D21="VAC",D21="BAJA",D21="AP",D21="HS"),"NO DISPONIBLE ("&D21&")",IF(F21<>"APTO","RESTRINGIDO (Noche a Mañana)",IF(AND(I21<>"",I21<=$G$10),IF(D21="D","¡ADJUDICADO LIBRE! (Plaza "&I21&")","¡ADJUDICADO DOBLANDO! (Plaza "&I21&")"),IF(D21="D","Inscrito Libre ("&G21&" ext)","Inscrito Doblado ("&G21&" ext)"))))) -> Inscrito Libre (0 ext)
B22: =IF(A22="","",IFERROR(VLOOKUP(A22,Policías!$A$5:$B$63,2,FALSE()),"")) | C22: =IF(A22="","",IFERROR(VLOOKUP(A22,Policías!$A$5:$C$63,3,FALSE()),"")) | D22: =IF(A22="","",INDEX(Cuadrante!$D$5:$AH$63,MATCH(A22,Cuadrante!$A$5:$A$63,0),MATCH(VLOOKUP($C$10,$A$6:$F$8,2,FALSE()),Cuadrante!$D$4:$AH$4,0))) | E22: =IF(A22="","",IFERROR(INDEX(Cuadrante!$D$5:$AH$63,MATCH(A22,Cuadrante!$A$5:$A$63,0),MATCH(VLOOKUP($C$10,$A$6:$F$8,2,FALSE()),Cuadrante!$D$4:$AH$4,0)-1),"N/A")) | F22: =IF(A22="","",IF(OR(AND(E22="N",VLOOKUP($C$10,$A$6:$F$8,3,FALSE())="Mañana"),AND(D22="N",VLOOKUP($C$10,$A$6:$F$8,3,FALSE())="Mañana")),"RESTRINGIDO (Noche a Mañana)","APTO")) | G22: =IF(A22="","",SUMIF(Historico_Extras!$C$5:$C$104,A22,Historico_Extras!$F$5:$F$104)) | H22: =IF(A22="","",IF(OR(F22<>"APTO",D22="VAC",D22="BAJA",D22="AP",D22="HS"),99999,IF(D22="D",G22*1000+ROW(),50000+G22*1000+ROW()))) | I22: =IF(OR(A22="",H22=99999),"",RANK(H22,$H$14:$H$33,1)) | J22: =IF(A22="","",IF(OR(D22="VAC",D22="BAJA",D22="AP",D22="HS"),"NO DISPONIBLE ("&D22&")",IF(F22<>"APTO","RESTRINGIDO (Noche a Mañana)",IF(AND(I22<>"",I22<=$G$10),IF(D22="D","¡ADJUDICADO LIBRE! (Plaza "&I22&")","¡ADJUDICADO DOBLANDO! (Plaza "&I22&")"),IF(D22="D","Inscrito Libre ("&G22&" ext)","Inscrito Doblado ("&G22&" ext)")))))
B23: =IF(A23="","",IFERROR(VLOOKUP(A23,Policías!$A$5:$B$63,2,FALSE()),"")) | C23: =IF(A23="","",IFERROR(VLOOKUP(A23,Policías!$A$5:$C$63,3,FALSE()),"")) | D23: =IF(A23="","",INDEX(Cuadrante!$D$5:$AH$63,MATCH(A23,Cuadrante!$A$5:$A$63,0),MATCH(VLOOKUP($C$10,$A$6:$F$8,2,FALSE()),Cuadrante!$D$4:$AH$4,0))) | E23: =IF(A23="","",IFERROR(INDEX(Cuadrante!$D$5:$AH$63,MATCH(A23,Cuadrante!$A$5:$A$63,0),MATCH(VLOOKUP($C$10,$A$6:$F$8,2,FALSE()),Cuadrante!$D$4:$AH$4,0)-1),"N/A")) | F23: =IF(A23="","",IF(OR(AND(E23="N",VLOOKUP($C$10,$A$6:$F$8,3,FALSE())="Mañana"),AND(D23="N",VLOOKUP($C$10,$A$6:$F$8,3,FALSE())="Mañana")),"RESTRINGIDO (Noche a Mañana)","APTO")) | G23: =IF(A23="","",SUMIF(Historico_Extras!$C$5:$C$104,A23,Historico_Extras!$F$5:$F$104)) | H23: =IF(A23="","",IF(OR(F23<>"APTO",D23="VAC",D23="BAJA",D23="AP",D23="HS"),99999,IF(D23="D",G23*1000+ROW(),50000+G23*1000+ROW()))) | I23: =IF(OR(A23="",H23=99999),"",RANK(H23,$H$14:$H$33,1)) | J23: =IF(A23="","",IF(OR(D23="VAC",D23="BAJA",D23="AP",D23="HS"),"NO DISPONIBLE ("&D23&")",IF(F23<>"APTO","RESTRINGIDO (Noche a Mañana)",IF(AND(I23<>"",I23<=$G$10),IF(D23="D","¡ADJUDICADO LIBRE! (Plaza "&I23&")","¡ADJUDICADO DOBLANDO! (Plaza "&I23&")"),IF(D23="D","Inscrito Libre ("&G23&" ext)","Inscrito Doblado ("&G23&" ext)")))))
B24: =IF(A24="","",IFERROR(VLOOKUP(A24,Policías!$A$5:$B$63,2,FALSE()),"")) | C24: =IF(A24="","",IFERROR(VLOOKUP(A24,Policías!$A$5:$C$63,3,FALSE()),"")) | D24: =IF(A24="","",INDEX(Cuadrante!$D$5:$AH$63,MATCH(A24,Cuadrante!$A$5:$A$63,0),MATCH(VLOOKUP($C$10,$A$6:$F$8,2,FALSE()),Cuadrante!$D$4:$AH$4,0))) | E24: =IF(A24="","",IFERROR(INDEX(Cuadrante!$D$5:$AH$63,MATCH(A24,Cuadrante!$A$5:$A$63,0),MATCH(VLOOKUP($C$10,$A$6:$F$8,2,FALSE()),Cuadrante!$D$4:$AH$4,0)-1),"N/A")) | F24: =IF(A24="","",IF(OR(AND(E24="N",VLOOKUP($C$10,$A$6:$F$8,3,FALSE())="Mañana"),AND(D24="N",VLOOKUP($C$10,$A$6:$F$8,3,FALSE())="Mañana")),"RESTRINGIDO (Noche a Mañana)","APTO")) | G24: =IF(A24="","",SUMIF(Historico_Extras!$C$5:$C$104,A24,Historico_Extras!$F$5:$F$104)) | H24: =IF(A24="","",IF(OR(F24<>"APTO",D24="VAC",D24="BAJA",D24="AP",D24="HS"),99999,IF(D24="D",G24*1000+ROW(),50000+G24*1000+ROW()))) | I24: =IF(OR(A24="",H24=99999),"",RANK(H24,$H$14:$H$33,1)) | J24: =IF(A24="","",IF(OR(D24="VAC",D24="BAJA",D24="AP",D24="HS"),"NO DISPONIBLE ("&D24&")",IF(F24<>"APTO","RESTRINGIDO (Noche a Mañana)",IF(AND(I24<>"",I24<=$G$10),IF(D24="D","¡ADJUDICADO LIBRE! (Plaza "&I24&")","¡ADJUDICADO DOBLANDO! (Plaza "&I24&")"),IF(D24="D","Inscrito Libre ("&G24&" ext)","Inscrito Doblado ("&G24&" ext)")))))
B25: =IF(A25="","",IFERROR(VLOOKUP(A25,Policías!$A$5:$B$63,2,FALSE()),"")) | C25: =IF(A25="","",IFERROR(VLOOKUP(A25,Policías!$A$5:$C$63,3,FALSE()),"")) | D25: =IF(A25="","",INDEX(Cuadrante!$D$5:$AH$63,MATCH(A25,Cuadrante!$A$5:$A$63,0),MATCH(VLOOKUP($C$10,$A$6:$F$8,2,FALSE()),Cuadrante!$D$4:$AH$4,0))) | E25: =IF(A25="","",IFERROR(INDEX(Cuadrante!$D$5:$AH$63,MATCH(A25,Cuadrante!$A$5:$A$63,0),MATCH(VLOOKUP($C$10,$A$6:$F$8,2,FALSE()),Cuadrante!$D$4:$AH$4,0)-1),"N/A")) | F25: =IF(A25="","",IF(OR(AND(E25="N",VLOOKUP($C$10,$A$6:$F$8,3,FALSE())="Mañana"),AND(D25="N",VLOOKUP($C$10,$A$6:$F$8,3,FALSE())="Mañana")),"RESTRINGIDO (Noche a Mañana)","APTO")) | G25: =IF(A25="","",SUMIF(Historico_Extras!$C$5:$C$104,A25,Historico_Extras!$F$5:$F$104)) | H25: =IF(A25="","",IF(OR(F25<>"APTO",D25="VAC",D25="BAJA",D25="AP",D25="HS"),99999,IF(D25="D",G25*1000+ROW(),50000+G25*1000+ROW()))) | I25: =IF(OR(A25="",H25=99999),"",RANK(H25,$H$14:$H$33,1)) | J25: =IF(A25="","",IF(OR(D25="VAC",D25="BAJA",D25="AP",D25="HS"),"NO DISPONIBLE ("&D25&")",IF(F25<>"APTO","RESTRINGIDO (Noche a Mañana)",IF(AND(I25<>"",I25<=$G$10),IF(D25="D","¡ADJUDICADO LIBRE! (Plaza "&I25&")","¡ADJUDICADO DOBLANDO! (Plaza "&I25&")"),IF(D25="D","Inscrito Libre ("&G25&" ext)","Inscrito Doblado ("&G25&" ext)")))))
B26: =IF(A26="","",IFERROR(VLOOKUP(A26,Policías!$A$5:$B$63,2,FALSE()),"")) | C26: =IF(A26="","",IFERROR(VLOOKUP(A26,Policías!$A$5:$C$63,3,FALSE()),"")) | D26: =IF(A26="","",INDEX(Cuadrante!$D$5:$AH$63,MATCH(A26,Cuadrante!$A$5:$A$63,0),MATCH(VLOOKUP($C$10,$A$6:$F$8,2,FALSE()),Cuadrante!$D$4:$AH$4,0))) | E26: =IF(A26="","",IFERROR(INDEX(Cuadrante!$D$5:$AH$63,MATCH(A26,Cuadrante!$A$5:$A$63,0),MATCH(VLOOKUP($C$10,$A$6:$F$8,2,FALSE()),Cuadrante!$D$4:$AH$4,0)-1),"N/A")) | F26: =IF(A26="","",IF(OR(AND(E26="N",VLOOKUP($C$10,$A$6:$F$8,3,FALSE())="Mañana"),AND(D26="N",VLOOKUP($C$10,$A$6:$F$8,3,FALSE())="Mañana")),"RESTRINGIDO (Noche a Mañana)","APTO")) | G26: =IF(A26="","",SUMIF(Historico_Extras!$C$5:$C$104,A26,Historico_Extras!$F$5:$F$104)) | H26: =IF(A26="","",IF(OR(F26<>"APTO",D26="VAC",D26="BAJA",D26="AP",D26="HS"),99999,IF(D26="D",G26*1000+ROW(),50000+G26*1000+ROW()))) | I26: =IF(OR(A26="",H26=99999),"",RANK(H26,$H$14:$H$33,1)) | J26: =IF(A26="","",IF(OR(D26="VAC",D26="BAJA",D26="AP",D26="HS"),"NO DISPONIBLE ("&D26&")",IF(F26<>"APTO","RESTRINGIDO (Noche a Mañana)",IF(AND(I26<>"",I26<=$G$10),IF(D26="D","¡ADJUDICADO LIBRE! (Plaza "&I26&")","¡ADJUDICADO DOBLANDO! (Plaza "&I26&")"),IF(D26="D","Inscrito Libre ("&G26&" ext)","Inscrito Doblado ("&G26&" ext)")))))
B27: =IF(A27="","",IFERROR(VLOOKUP(A27,Policías!$A$5:$B$63,2,FALSE()),"")) | C27: =IF(A27="","",IFERROR(VLOOKUP(A27,Policías!$A$5:$C$63,3,FALSE()),"")) | D27: =IF(A27="","",INDEX(Cuadrante!$D$5:$AH$63,MATCH(A27,Cuadrante!$A$5:$A$63,0),MATCH(VLOOKUP($C$10,$A$6:$F$8,2,FALSE()),Cuadrante!$D$4:$AH$4,0))) | E27: =IF(A27="","",IFERROR(INDEX(Cuadrante!$D$5:$AH$63,MATCH(A27,Cuadrante!$A$5:$A$63,0),MATCH(VLOOKUP($C$10,$A$6:$F$8,2,FALSE()),Cuadrante!$D$4:$AH$4,0)-1),"N/A")) | F27: =IF(A27="","",IF(OR(AND(E27="N",VLOOKUP($C$10,$A$6:$F$8,3,FALSE())="Mañana"),AND(D27="N",VLOOKUP($C$10,$A$6:$F$8,3,FALSE())="Mañana")),"RESTRINGIDO (Noche a Mañana)","APTO")) | G27: =IF(A27="","",SUMIF(Historico_Extras!$C$5:$C$104,A27,Historico_Extras!$F$5:$F$104)) | H27: =IF(A27="","",IF(OR(F27<>"APTO",D27="VAC",D27="BAJA",D27="AP",D27="HS"),99999,IF(D27="D",G27*1000+ROW(),50000+G27*1000+ROW()))) | I27: =IF(OR(A27="",H27=99999),"",RANK(H27,$H$14:$H$33,1)) | J27: =IF(A27="","",IF(OR(D27="VAC",D27="BAJA",D27="AP",D27="HS"),"NO DISPONIBLE ("&D27&")",IF(F27<>"APTO","RESTRINGIDO (Noche a Mañana)",IF(AND(I27<>"",I27<=$G$10),IF(D27="D","¡ADJUDICADO LIBRE! (Plaza "&I27&")","¡ADJUDICADO DOBLANDO! (Plaza "&I27&")"),IF(D27="D","Inscrito Libre ("&G27&" ext)","Inscrito Doblado ("&G27&" ext)")))))
B28: =IF(A28="","",IFERROR(VLOOKUP(A28,Policías!$A$5:$B$63,2,FALSE()),"")) | C28: =IF(A28="","",IFERROR(VLOOKUP(A28,Policías!$A$5:$C$63,3,FALSE()),"")) | D28: =IF(A28="","",INDEX(Cuadrante!$D$5:$AH$63,MATCH(A28,Cuadrante!$A$5:$A$63,0),MATCH(VLOOKUP($C$10,$A$6:$F$8,2,FALSE()),Cuadrante!$D$4:$AH$4,0))) | E28: =IF(A28="","",IFERROR(INDEX(Cuadrante!$D$5:$AH$63,MATCH(A28,Cuadrante!$A$5:$A$63,0),MATCH(VLOOKUP($C$10,$A$6:$F$8,2,FALSE()),Cuadrante!$D$4:$AH$4,0)-1),"N/A")) | F28: =IF(A28="","",IF(OR(AND(E28="N",VLOOKUP($C$10,$A$6:$F$8,3,FALSE())="Mañana"),AND(D28="N",VLOOKUP($C$10,$A$6:$F$8,3,FALSE())="Mañana")),"RESTRINGIDO (Noche a Mañana)","APTO")) | G28: =IF(A28="","",SUMIF(Historico_Extras!$C$5:$C$104,A28,Historico_Extras!$F$5:$F$104)) | H28: =IF(A28="","",IF(OR(F28<>"APTO",D28="VAC",D28="BAJA",D28="AP",D28="HS"),99999,IF(D28="D",G28*1000+ROW(),50000+G28*1000+ROW()))) | I28: =IF(OR(A28="",H28=99999),"",RANK(H28,$H$14:$H$33,1)) | J28: =IF(A28="","",IF(OR(D28="VAC",D28="BAJA",D28="AP",D28="HS"),"NO DISPONIBLE ("&D28&")",IF(F28<>"APTO","RESTRINGIDO (Noche a Mañana)",IF(AND(I28<>"",I28<=$G$10),IF(D28="D","¡ADJUDICADO LIBRE! (Plaza "&I28&")","¡ADJUDICADO DOBLANDO! (Plaza "&I28&")"),IF(D28="D","Inscrito Libre ("&G28&" ext)","Inscrito Doblado ("&G28&" ext)")))))
B29: =IF(A29="","",IFERROR(VLOOKUP(A29,Policías!$A$5:$B$63,2,FALSE()),"")) | C29: =IF(A29="","",IFERROR(VLOOKUP(A29,Policías!$A$5:$C$63,3,FALSE()),"")) | D29: =IF(A29="","",INDEX(Cuadrante!$D$5:$AH$63,MATCH(A29,Cuadrante!$A$5:$A$63,0),MATCH(VLOOKUP($C$10,$A$6:$F$8,2,FALSE()),Cuadrante!$D$4:$AH$4,0))) | E29: =IF(A29="","",IFERROR(INDEX(Cuadrante!$D$5:$AH$63,MATCH(A29,Cuadrante!$A$5:$A$63,0),MATCH(VLOOKUP($C$10,$A$6:$F$8,2,FALSE()),Cuadrante!$D$4:$AH$4,0)-1),"N/A")) | F29: =IF(A29="","",IF(OR(AND(E29="N",VLOOKUP($C$10,$A$6:$F$8,3,FALSE())="Mañana"),AND(D29="N",VLOOKUP($C$10,$A$6:$F$8,3,FALSE())="Mañana")),"RESTRINGIDO (Noche a Mañana)","APTO")) | G29: =IF(A29="","",SUMIF(Historico_Extras!$C$5:$C$104,A29,Historico_Extras!$F$5:$F$104)) | H29: =IF(A29="","",IF(OR(F29<>"APTO",D29="VAC",D29="BAJA",D29="AP",D29="HS"),99999,IF(D29="D",G29*1000+ROW(),50000+G29*1000+ROW()))) | I29: =IF(OR(A29="",H29=99999),"",RANK(H29,$H$14:$H$33,1)) | J29: =IF(A29="","",IF(OR(D29="VAC",D29="BAJA",D29="AP",D29="HS"),"NO DISPONIBLE ("&D29&")",IF(F29<>"APTO","RESTRINGIDO (Noche a Mañana)",IF(AND(I29<>"",I29<=$G$10),IF(D29="D","¡ADJUDICADO LIBRE! (Plaza "&I29&")","¡ADJUDICADO DOBLANDO! (Plaza "&I29&")"),IF(D29="D","Inscrito Libre ("&G29&" ext)","Inscrito Doblado ("&G29&" ext)")))))
B30: =IF(A30="","",IFERROR(VLOOKUP(A30,Policías!$A$5:$B$63,2,FALSE()),"")) | C30: =IF(A30="","",IFERROR(VLOOKUP(A30,Policías!$A$5:$C$63,3,FALSE()),"")) | D30: =IF(A30="","",INDEX(Cuadrante!$D$5:$AH$63,MATCH(A30,Cuadrante!$A$5:$A$63,0),MATCH(VLOOKUP($C$10,$A$6:$F$8,2,FALSE()),Cuadrante!$D$4:$AH$4,0))) | E30: =IF(A30="","",IFERROR(INDEX(Cuadrante!$D$5:$AH$63,MATCH(A30,Cuadrante!$A$5:$A$63,0),MATCH(VLOOKUP($C$10,$A$6:$F$8,2,FALSE()),Cuadrante!$D$4:$AH$4,0)-1),"N/A")) | F30: =IF(A30="","",IF(OR(AND(E30="N",VLOOKUP($C$10,$A$6:$F$8,3,FALSE())="Mañana"),AND(D30="N",VLOOKUP($C$10,$A$6:$F$8,3,FALSE())="Mañana")),"RESTRINGIDO (Noche a Mañana)","APTO")) | G30: =IF(A30="","",SUMIF(Historico_Extras!$C$5:$C$104,A30,Historico_Extras!$F$5:$F$104)) | H30: =IF(A30="","",IF(OR(F30<>"APTO",D30="VAC",D30="BAJA",D30="AP",D30="HS"),99999,IF(D30="D",G30*1000+ROW(),50000+G30*1000+ROW()))) | I30: =IF(OR(A30="",H30=99999),"",RANK(H30,$H$14:$H$33,1)) | J30: =IF(A30="","",IF(OR(D30="VAC",D30="BAJA",D30="AP",D30="HS"),"NO DISPONIBLE ("&D30&")",IF(F30<>"APTO","RESTRINGIDO (Noche a Mañana)",IF(AND(I30<>"",I30<=$G$10),IF(D30="D","¡ADJUDICADO LIBRE! (Plaza "&I30&")","¡ADJUDICADO DOBLANDO! (Plaza "&I30&")"),IF(D30="D","Inscrito Libre ("&G30&" ext)","Inscrito Doblado ("&G30&" ext)")))))
